Workbook

Sheet Solicitud
A1: COOPERATIVA MIXTA DE FARMACÉUTICOS DE HONDURAS (COMIFARH)
A3: SOLICITUD DE PRÉSTAMO HIPOTECARIO
A5: RESUMEN DEL CRÉDITO
A6: Valor avalúo (L) | B6: =B48 -> 0
A7: Monto máximo (80%) | B7: =B49 -> 0
A8: Monto solicitado (L) | B8: =B33 -> 0
A9: Plazo (meses) | B9: =B34 -> 0
A10: Tasa anual | B10: ='Análisis de Crédito'!B5 -> 0.1
A11: Cuota estimada | B11: =Amortización!F12 -> 0
A12: Relación LTV | B12: =IF(B6=0,0,B8/B6) -> 0
A14: I. DATOS GENERALES DEL SOLICITANTE
A15: Fecha de solicitud
A16: Número de asociado
A17: Nombre completo
A18: Tipo de identificación
A19: Número de identificación
A20: Fecha de nacimiento
A21: Estado civil
A22: Dirección completa
A23: Departamento
A24: Municipio
A25: Teléfono
... A48: Valor de avalúo (L)
A49: Monto máximo permitido (80% avalúo) (L) | B49: =B48*0.8 -> 0
A50: ¿Seguro de deuda endosado a COMIFARH?
A51: ¿Seguro del bien endosado a COMIFARH?
A52: No. póliza seguro deuda
A53: No. póliza seguro bien
A54: Aportación mensual vigente (L)
A55: V. REFERENCIAS PERSONALES (No convivientes)
A56: Referencia 1 - Nombre
A57: Referencia 1 - Parentesco
A58: Referencia 1 - Teléfono
A59: Referencia 2 - Nombre
A60: Referencia 2 - Parentesco
A61: Referencia 2 - Teléfono
... A77: CHECKLIST (marque): ☐ Identidad ☐ RTN (si aplica) ☐ Escritura ☐ Avalúo ☐ Certificación libertad de gravamen ☐ Seguro de deuda endosado ☐ Seguro del bien endosado ☐ Otros

Sheet Listas
A1: tipo_id | B1: DNI | C1: RTN | D1: Pasaporte
A2: estado_civil | B2: Soltero(a) | C2: Casado(a) | D2: Unión libre | E2: Divorciado(a) | F2: Viudo(a)
A3: cond_laboral | B3: Empleado(a) público | C3: Empleado(a) privado | D3: Negocio propio | E3: Jubilado(a)
A4: plazo | B4: 12 | C4: 24 | D4: 36 | E4: 48 | F4: 60 | G4: 72 | H4: 84 | I4: 96 | J4: 108 | K4: 120
A5: forma_pago | B5: Deducción por planilla | C5: Pago en ventanilla | D5: Transferencia bancaria
A6: destino | B6: Vivienda | C6: Mejoras/Remodelación | D6: Compra de lote | E6: Consolidación | F6: Otro
A7: parentesco | B7: Familiar | C7: Amistad
A8: recomendacion | B8: Aprobado | C8: Condicionado | D8: Rechazado
A9: si_no | B9: Sí | C9: No
A10: tipo_inmueble | B10: Casa | C10: Apartamento | D10: Terreno | E10: Local comercial | F10: Otro
A11: departamento | B11: Atlántida | C11: Choluteca | D11: Colón | E11: Comayagua | F11: Copán | G11: Cortés | H11: El Paraíso | I11: Francisco Morazán | J11: Gracias a Dios | K11: Intibucá | L11: Islas de la Bahía | M11: La Paz | N11: Lempira | O11: Ocotepeque | P11: Olancho | Q11: Santa Bárbara | R11: Valle | S11: Yoro

Sheet Análisis de Crédito
A1: ANÁLISIS DE CRÉDITO – PRÉSTAMO HIPOTECARIO (COMIFARH)
A4: 1) PARÁMETROS
A5: Tasa anual hipotecario | B5: 0.1 | D5: Referencia: Hipotecario 10% anual
A6: LTV máximo (sobre avalúo) | B6: 0.8 | D6: Referencia: se presta 80% del avalúo
A7: Plazo máximo (meses) | B7: 120 | D7: Referencia: plazo máx. 120 meses
A8: Máx. deuda/ingreso neto | B8: 0.3 | D8: Política general: deuda ≤ 30% ingreso neto
A10: 2) DATOS (desde Solicitud)
A11: Ingreso mensual neto (L) | B11: =Solicitud!B31 -> 0
A12: Valor de avalúo (L) | B12: =Solicitud!B48 -> 0
A13: Monto solicitado (L) | B13: =Solicitud!B33 -> 0
A14: Plazo solicitado (meses) | B14: =Solicitud!B34 -> 0
A15: Aportación mensual vigente (L) | B15: =Solicitud!B54 -> 0
A17: 3) VALIDACIONES Y CÁLCULO
A18: Monto máximo permitido (L) | B18: =B12*$B$6 -> 0
A19: Tasa mensual | B19: =$B$5/12 -> 0.0083333333
A20: Cuota mensual estimada (L) | B20: =-PMT(B19,B14,B13) -> #NUM!
A21: Cuota total (incluye aportación) (L) | B21: =B20+B15 -> #NUM!
A22: Relación cuota/ingreso (%) | B22: =B20/B11 -> #NUM!
A23: Cumple monto ≤ máximo | B23: =IF(B13<=B18,"SÍ","NO") -> SÍ
A24: Cumple plazo ≤ máximo | B24: =IF(B14<=$B$7,"SÍ","NO") -> SÍ
A25: Cumple cuota/ingreso ≤ límite | B25: =IF(B22<=$B$8,"SÍ","NO") -> #NUM!
A27: 4) DICTAMEN
A28: Dictamen del analista | D28: Observaciones y condiciones
A29: Recomendación final | B29: =IF(AND(B23="SÍ",B24="SÍ",B25="SÍ"),"APROBABLE","REVISAR / CONDICIONAR") -> #NUM!

Sheet Amortización
A1: TABLA DE AMORTIZACIÓN – PRÉSTAMO HIPOTECARIO
A3: CLIENTE: | C3: =Solicitud!B17 -> 0
A4: Gastos Operativos | C4: 0.03 | D4: =SUM(C12*C4) -> 0
A5: Aportaciones | C5: 0.05 | D5: =SUM(C12*C5) -> 0
A6: Tasa de Seguridad
A7: Cancelación Préstamo | D7: 0
A8: Total deducciones | D8: =SUM(D4:D7) -> 0
A9: Total a desembolsar | D9: =SUM(C12-D8) -> 0 | E9: FECHAS: | F9: Inicio | G9: Final
F10: 46142 | G10: 49795
C11: MONTO | D11: PLAZO | E11: TASA | F11: CUOTA | G11: Cuota+Aport
A12: Principal | C12: ='Análisis de Crédito'!B13 -> 0 | D12: ='Análisis de Crédito'!B7 -> 120 | E12: ='Análisis de Crédito'!B5 -> 0.1 | F12: =C12/((1-((1+(E12/12))^-D12))/(E12/12)) -> 0 | G12: =F12+Solicitud!B54 -> 0
A13: Plazo (meses)
A14: Tasa anual
A15: Cuota (fórmula)
A16: Fecha 1er pago | C16: =Solicitud!B38 -> 0
A18: # | B18: Fecha | C18: Saldo inicial | D18: Cuota | E18: Interés | F18: Capital | G18: Saldo final
A19: =IF(1<=$D$12,1,"") -> 1 | B19: =IF(1<=$D$12,IF($C$16="","",EDATE($C$16,1-1)),"") -> 0 | C19: =IF(1<=$D$12,IF(1=1,$C$12,G18),"") -> 0 | D19: =IF(1<=$D$12,$F$12,"") -> 0 | E19: =IF(1<=$D$12,C19*($E$12/12),"") -> 0 | F19: =IF(1<=$D$12,D19-E19,"") -> 0 | G19: =IF(1<=$D$12,MAX(0,C19-F19),"") -> 0
A20: =IF(2<=$D$12,2,"") -> 2 | B20: =IF(2<=$D$12,IF($C$16="","",EDATE($C$16,2-1)),"") -> 31 | C20: =IF(2<=$D$12,IF(2=1,$C$12,G19),"") -> 0 | D20: =IF(2<=$D$12,$F$12,"") -> 0 | E20: =IF(2<=$D$12,C20*($E$12/12),"") -> 0 | F20: =IF(2<=$D$12,D20-E20,"") -> 0 | G20: =IF(2<=$D$12,MAX(0,C20-F20),"") -> 0
A21: =IF(3<=$D$12,3,"") -> 3 | B21: =IF(3<=$D$12,IF($C$16="","",EDATE($C$16,3-1)),"") -> 60 | C21: =IF(3<=$D$12,IF(3=1,$C$12,G20),"") -> 0 | D21: =IF(3<=$D$12,$F$12,"") -> 0 | E21: =IF(3<=$D$12,C21*($E$12/12),"") -> 0 | F21: =IF(3<=$D$12,D21-E21,"") -> 0 | G21: =IF(3<=$D$12,MAX(0,C21-F21),"") -> 0
A22: =IF(4<=$D$12,4,"") -> 4 | B22: =IF(4<=$D$12,IF($C$16="","",EDATE($C$16,4-1)),"") -> 91 | C22: =IF(4<=$D$12,IF(4=1,$C$12,G21),"") -> 0 | D22: =IF(4<=$D$12,$F$12,"") -> 0 | E22: =IF(4<=$D$12,C22*($E$12/12),"") -> 0 | F22: =IF(4<=$D$12,D22-E22,"") -> 0 | G22: =IF(4<=$D$12,MAX(0,C22-F22),"") -> 0
A23: =IF(5<=$D$12,5,"") -> 5 | B23: =IF(5<=$D$12,IF($C$16="","",EDATE($C$16,5-1)),"") -> 121 | C23: =IF(5<=$D$12,IF(5=1,$C$12,G22),"") -> 0 | D23: =IF(5<=$D$12,$F$12,"") -> 0 | E23: =IF(5<=$D$12,C23*($E$12/12),"") -> 0 | F23: =IF(5<=$D$12,D23-E23,"") -> 0 | G23: =IF(5<=$D$12,MAX(0,C23-F23),"") -> 0
A24: =IF(6<=$D$12,6,"") -> 6 | B24: =IF(6<=$D$12,IF($C$16="","",EDATE($C$16,6-1)),"") -> 152 | C24: =IF(6<=$D$12,IF(6=1,$C$12,G23),"") -> 0 | D24: =IF(6<=$D$12,$F$12,"") -> 0 | E24: =IF(6<=$D$12,C24*($E$12/12),"") -> 0 | F24: =IF(6<=$D$12,D24-E24,"") -> 0 | G24: =IF(6<=$D$12,MAX(0,C24-F24),"") -> 0
A25: =IF(7<=$D$12,7,"") -> 7 | B25: =IF(7<=$D$12,IF($C$16="","",EDATE($C$16,7-1)),"") -> 182 | C25: =IF(7<=$D$12,IF(7=1,$C$12,G24),"") -> 0 | D25: =IF(7<=$D$12,$F$12,"") -> 0 | E25: =IF(7<=$D$12,C25*($E$12/12),"") -> 0 | F25: =IF(7<=$D$12,D25-E25,"") -> 0 | G25: =IF(7<=$D$12,MAX(0,C25-F25),"") -> 0
A26: =IF(8<=$D$12,8,"") -> 8 | B26: =IF(8<=$D$12,IF($C$16="","",EDATE($C$16,8-1)),"") -> 213 | C26: =IF(8<=$D$12,IF(8=1,$C$12,G25),"") -> 0 | D26: =IF(8<=$D$12,$F$12,"") -> 0 | E26: =IF(8<=$D$12,C26*($E$12/12),"") -> 0 | F26: =IF(8<=$D$12,D26-E26,"") -> 0 | G26: =IF(8<=$D$12,MAX(0,C26-F26),"") -> 0
A27: =IF(9<=$D$12,9,"") -> 9 | B27: =IF(9<=$D$12,IF($C$16="","",EDATE($C$16,9-1)),"") -> 244 | C27: =IF(9<=$D$12,IF(9=1,$C$12,G26),"") -> 0 | D27: =IF(9<=$D$12,$F$12,"") -> 0 | E27: =IF(9<=$D$12,C27*($E$12/12),"") -> 0 | F27: =IF(9<=$D$12,D27-E27,"") -> 0 | G27: =IF(9<=$D$12,MAX(0,C27-F27),"") -> 0
A28: =IF(10<=$D$12,10,"") -> 10 | B28: =IF(10<=$D$12,IF($C$16="","",EDATE($C$16,10-1)),"") -> 274 | C28: =IF(10<=$D$12,IF(10=1,$C$12,G27),"") -> 0 | D28: =IF(10<=$D$12,$F$12,"") -> 0 | E28: =IF(10<=$D$12,C28*($E$12/12),"") -> 0 | F28: =IF(10<=$D$12,D28-E28,"") -> 0 | G28: =IF(10<=$D$12,MAX(0,C28-F28),"") -> 0
A29: =IF(11<=$D$12,11,"") -> 11 | B29: =IF(11<=$D$12,IF($C$16="","",EDATE($C$16,11-1)),"") -> 305 | C29: =IF(11<=$D$12,IF(11=1,$C$12,G28),"") -> 0 | D29: =IF(11<=$D$12,$F$12,"") -> 0 | E29: =IF(11<=$D$12,C29*($E$12/12),"") -> 0 | F29: =IF(11<=$D$12,D29-E29,"") -> 0 | G29: =IF(11<=$D$12,MAX(0,C29-F29),"") -> 0
A30: =IF(12<=$D$12,12,"") -> 12 | B30: =IF(12<=$D$12,IF($C$16="","",EDATE($C$16,12-1)),"") -> 335 | C30: =IF(12<=$D$12,IF(12=1,$C$12,G29),"") -> 0 | D30: =IF(12<=$D$12,$F$12,"") -> 0 | E30: =IF(12<=$D$12,C30*($E$12/12),"") -> 0 | F30: =IF(12<=$D$12,D30-E30,"") -> 0 | G30: =IF(12<=$D$12,MAX(0,C30-F30),"") -> 0
A31: =IF(13<=$D$12,13,"") -> 13 | B31: =IF(13<=$D$12,IF($C$16="","",EDATE($C$16,13-1)),"") -> 366 | C31: =IF(13<=$D$12,IF(13=1,$C$12,G30),"") -> 0 | D31: =IF(13<=$D$12,$F$12,"") -> 0 | E31: =IF(13<=$D$12,C31*($E$12/12),"") -> 0 | F31: =IF(13<=$D$12,D31-E31,"") -> 0 | G31: =IF(13<=$D$12,MAX(0,C31-F31),"") -> 0
A32: =IF(14<=$D$12,14,"") -> 14 | B32: =IF(14<=$D$12,IF($C$16="","",EDATE($C$16,14-1)),"") -> 397 | C32: =IF(14<=$D$12,IF(14=1,$C$12,G31),"") -> 0 | D32: =IF(14<=$D$12,$F$12,"") -> 0 | E32: =IF(14<=$D$12,C32*($E$12/12),"") -> 0 | F32: =IF(14<=$D$12,D32-E32,"") -> 0 | G32: =IF(14<=$D$12,MAX(0,C32-F32),"") -> 0
A33: =IF(15<=$D$12,15,"") -> 15 | B33: =IF(15<=$D$12,IF($C$16="","",EDATE($C$16,15-1)),"") -> 425 | C33: =IF(15<=$D$12,IF(15=1,$C$12,G32),"") -> 0 | D33: =IF(15<=$D$12,$F$12,"") -> 0 | E33: =IF(15<=$D$12,C33*($E$12/12),"") -> 0 | F33: =IF(15<=$D$12,D33-E33,"") -> 0 | G33: =IF(15<=$D$12,MAX(0,C33-F33),"") -> 0
A34: =IF(16<=$D$12,16,"") -> 16 | B34: =IF(16<=$D$12,IF($C$16="","",EDATE($C$16,16-1)),"") -> 456 | C34: =IF(16<=$D$12,IF(16=1,$C$12,G33),"") -> 0 | D34: =IF(16<=$D$12,$F$12,"") -> 0 | E34: =IF(16<=$D$12,C34*($E$12/12),"") -> 0 | F34: =IF(16<=$D$12,D34-E34,"") -> 0 | G34: =IF(16<=$D$12,MAX(0,C34-F34),"") -> 0
A35: =IF(17<=$D$12,17,"") -> 17 | B35: =IF(17<=$D$12,IF($C$16="","",EDATE($C$16,17-1)),"") -> 486 | C35: =IF(17<=$D$12,IF(17=1,$C$12,G34),"") -> 0 | D35: =IF(17<=$D$12,$F$12,"") -> 0 | E35: =IF(17<=$D$12,C35*($E$12/12),"") -> 0 | F35: =IF(17<=$D$12,D35-E35,"") -> 0 | G35: =IF(17<=$D$12,MAX(0,C35-F35),"") -> 0
A36: =IF(18<=$D$12,18,"") -> 18 | B36: =IF(18<=$D$12,IF($C$16="","",EDATE($C$16,18-1)),"") -> 517 | C36: =IF(18<=$D$12,IF(18=1,$C$12,G35),"") -> 0 | D36: =IF(18<=$D$12,$F$12,"") -> 0 | E36: =IF(18<=$D$12,C36*($E$12/12),"") -> 0 | F36: =IF(18<=$D$12,D36-E36,"") -> 0 | G36: =IF(18<=$D$12,MAX(0,C36-F36),"") -> 0
A37: =IF(19<=$D$12,19,"") -> 19 | B37: =IF(19<=$D$12,IF($C$16="","",EDATE($C$16,19-1)),"") -> 547 | C37: =IF(19<=$D$12,IF(19=1,$C$12,G36),"") -> 0 | D37: =IF(19<=$D$12,$F$12,"") -> 0 | E37: =IF(19<=$D$12,C37*($E$12/12),"") -> 0 | F37: =IF(19<=$D$12,D37-E37,"") -> 0 | G37: =IF(19<=$D$12,MAX(0,C37-F37),"") -> 0
A38: =IF(20<=$D$12,20,"") -> 20 | B38: =IF(20<=$D$12,IF($C$16="","",EDATE($C$16,20-1)),"") -> 578 | C38: =IF(20<=$D$12,IF(20=1,$C$12,G37),"") -> 0 | D38: =IF(20<=$D$12,$F$12,"") -> 0 | E38: =IF(20<=$D$12,C38*($E$12/12),"") -> 0 | F38: =IF(20<=$D$12,D38-E38,"") -> 0 | G38: =IF(20<=$D$12,MAX(0,C38-F38),"") -> 0
A39: =IF(21<=$D$12,21,"") -> 21 | B39: =IF(21<=$D$12,IF($C$16="","",EDATE($C$16,21-1)),"") -> 609 | C39: =IF(21<=$D$12,IF(21=1,$C$12,G38),"") -> 0 | D39: =IF(21<=$D$12,$F$12,"") -> 0 | E39: =IF(21<=$D$12,C39*($E$12/12),"") -> 0 | F39: =IF(21<=$D$12,D39-E39,"") -> 0 | G39: =IF(21<=$D$12,MAX(0,C39-F39),"") -> 0
A40: =IF(22<=$D$12,22,"") -> 22 | B40: =IF(22<=$D$12,IF($C$16="","",EDATE($C$16,22-1)),"") -> 639 | C40: =IF(22<=$D$12,IF(22=1,$C$12,G39),"") -> 0 | D40: =IF(22<=$D$12,$F$12,"") -> 0 | E40: =IF(22<=$D$12,C40*($E$12/12),"") -> 0 | F40: =IF(22<=$D$12,D40-E40,"") -> 0 | G40: =IF(22<=$D$12,MAX(0,C40-F40),"") -> 0
A41: =IF(23<=$D$12,23,"") -> 23 | B41: =IF(23<=$D$12,IF($C$16="","",EDATE($C$16,23-1)),"") -> 670 | C41: =IF(23<=$D$12,IF(23=1,$C$12,G40),"") -> 0 | D41: =IF(23<=$D$12,$F$12,"") -> 0 | E41: =IF(23<=$D$12,C41*($E$12/12),"") -> 0 | F41: =IF(23<=$D$12,D41-E41,"") -> 0 | G41: =IF(23<=$D$12,MAX(0,C41-F41),"") -> 0
A42: =IF(24<=$D$12,24,"") -> 24 | B42: =IF(24<=$D$12,IF($C$16="","",EDATE($C$16,24-1)),"") -> 700 | C42: =IF(24<=$D$12,IF(24=1,$C$12,G41),"") -> 0 | D42: =IF(24<=$D$12,$F$12,"") -> 0 | E42: =IF(24<=$D$12,C42*($E$12/12),"") -> 0 | F42: =IF(24<=$D$12,D42-E42,"") -> 0 | G42: =IF(24<=$D$12,MAX(0,C42-F42),"") -> 0
...
