Workbook

Sheet Solicitud
A1: COOPERATIVA MIXTA DE FARMACÉUTICOS DE HONDURAS (COMIFARH)
A3: SOLICITUD DE PRÉSTAMO FIDUCIARIO
A4: RESUMEN DEL CRÉDITO
A5: Monto solicitado (L) | B5: =B35 -> 0
A6: Plazo (meses) | B6: =B36 -> 0
A7: Tasa anual | B7: ='Análisis de Crédito'!B5 -> 0.18
A8: Cuota estimada | B8: =Amortización!F12 -> #DIV/0!
A9: Retención 5% | B9: =B35*'Análisis de Crédito'!B7 -> 0
A10: Gastos 3% | B10: =B35*'Análisis de Crédito'!B8 -> 0
A11: Desembolso neto | B11: =B35-B9-B10 -> 0
A13: I. DATOS GENERALES DEL SOLICITANTE
A14: Fecha de solicitud
A15: Número de asociado
A16: Nombre completo
A17: Tipo de identificación
A18: Número de identificación
A19: Fecha de nacimiento
A20: Estado civil
A21: Dirección completa
A22: Departamento
A23: Municipio
A24: Teléfono
... A80: CHECKLIST DE DOCUMENTOS (marque): ☐ Identidad ☐ Constancia de trabajo/Estados fin. ☐ RTN (si aplica) ☐ Aval o Seguro de deuda ☐ Otros

Sheet Listas
A1: tipo_id | B1: DNI | C1: RTN | D1: Pasaporte
A2: estado_civil | B2: Soltero(a) | C2: Casado(a) | D2: Unión libre | E2: Divorciado(a) | F2: Viudo(a)
A3: cond_laboral | B3: Empleado(a) público | C3: Empleado(a) privado | D3: Negocio propio | E3: Jubilado(a)
A4: plazo | B4: 6 | C4: 12 | D4: 18 | E4: 24 | F4: 36 | G4: 48 | H4: 60 | I4: 72
A5: forma_pago | B5: Deducción por planilla | C5: Pago en ventanilla | D5: Transferencia bancaria
A6: destino | B6: Consumo personal | C6: Educación | D6: Salud | E6: Consolidación de deudas | F6: Vivienda | G6: Otro
A7: parentesco | B7: Familiar | C7: Amistad
A8: recomendacion | B8: Aprobado | C8: Condicionado | D8: Rechazado
A9: si_no | B9: Sí | C9: No
A10: departamento | B10: Atlántida | C10: Choluteca | D10: Colón | E10: Comayagua | F10: Copán | G10: Cortés | H10: El Paraíso | I10: Francisco Morazán | J10: Gracias a Dios | K10: Intibucá | L10: Islas de la Bahía | M10: La Paz | N10: Lempira | O10: Ocotepeque | P10: Olancho | Q10: Santa Bárbara | R10: Valle | S10: Yoro
A11: aval_es_socio | B11: Socio | C11: No socio
A12: relacion_aval | B12: Familiar | C12: Amistad | D12: Compañero(a) de trabajo | E12: Otro

Sheet Análisis de Crédito
A1: ANÁLISIS DE CRÉDITO – PRÉSTAMO FIDUCICIARIO (COMIFARH)
A4: 1) PARÁMETROS
A5: Tasa anual fiduciario | B5: 0.18 | D5: Editable por analista/Junta Directiva
A6: Máx. relación deuda/ingreso neto | B6: 0.3 | D6: Editable
A7: Retención a aportaciones | B7: 0.05 | D7: Editable
A8: Gastos operativos | B8: 0.03 | D8: Editable
A9: Techo fiduciario (L) | B9: 300000 | D9: Editable
A10: Plazo máximo permitido (meses) | B10: 72 | D10: Editable
A12: 2) DATOS (desde Solicitud)
A13: Ingreso mensual neto (L) | B13: =Solicitud!B33 -> 0
A14: Total aportaciones (L) | B14: =Solicitud!B42 -> 0
A15: Monto solicitado (L) | B15: =Solicitud!B35 -> 0
A16: Plazo solicitado (meses) | B16: =Solicitud!B36 -> 0
A17: Aportación mensual vigente (L) | B17: =Solicitud!B45 -> 0
A19: 3) OBLIGACIONES (ingrese)
A20: Cuotas de préstamos vigentes (L)
A21: Gastos fijos estimados (L) | B21: 3000
A22: Total egresos (L) | B22: =SUM(B20:B21) -> 3000
A24: 4) CÁLCULO
A25: Monto máximo por aportaciones (5x) (L) | B25: =5*B14 -> 0
A26: Monto máximo permitido (L) | B26: =MIN(B25,$B$9) -> 0
A27: Tasa mensual | B27: =$B$5/12 -> 0.015
A28: Retención 5% (L) | B28: =B15*$B$7 -> 0
A29: Gastos operativos 3% (L) | B29: =B15*$B$8 -> 0
A30: Desembolso neto estimado (L) | B30: =B15-B28-B29 -> 0
A31: Cuota mensual estimada (L) | B31: =-PMT(B27,B16,B15) -> #NUM!
A32: Cuota total (incluye aportación) (L) | B32: =B31+B17 -> #NUM!
A33: Relación deuda/ingreso neto (%) | B33: =(B32+B22)/B13 -> #NUM!
A34: Cumple relación ≤ límite | B34: =IF(B33<=$B$6,"SÍ","NO") -> #NUM!
A35: Cumple monto ≤ máximo | B35: =IF(B16<=B26,"SÍ","NO") -> SÍ
A36: Plazo dentro del máximo | B36: =IF(B16<=$B$10,"SÍ","NO") -> SÍ
A37: Cumple aval o seguro | B37: =IF(OR(Solicitud!B43="Sí",Solicitud!B44="Sí"),"SÍ","NO") -> NO
A39: 5) DICTAMEN
A40: Dictamen del analista | D40: Escriba conclusiones y condiciones.
A41: Recomendación final | B41: =IF(AND(B34="SÍ",B35="SÍ",B36="SÍ",B37="SÍ"),"APROBABLE","REVISAR / CONDICIONAR") -> #NUM!

Sheet Amortización
A1: TABLA DE AMORTIZACIÓN – PRÉSTAMO FIDUCIARIO
A3: CLIENTE: | C3: =Solicitud!B16 -> 0
A4: Gastos Operativos | C4: 0.03 | D4: =SUM(C12*C4) -> 0
A5: Aportaciones | C5: 0.05 | D5: =SUM(C12*C5) -> 0
A6: Tasa de Seguridad
A7: Cancelación Préstamo | D7: 0
A8: Total deducciones | D8: =SUM(D4:D7) -> 0
A9: Total a desembolsar | D9: =SUM(C12-D8) -> 0 | E9: FECHAS: | F9: Inicio | G9: Final
C11: MONTO | D11: PLAZO | E11: TASA | F11: CUOTA | G11: Cuota+Aport
B12: Principal | C12: =Solicitud!B35 -> 0 | D12: =Solicitud!B36 -> 0 | E12: ='Análisis de Crédito'!B5 -> 0.18 | F12: =C12/((1-((1+(E12/12))^-D12))/(E12/12)) -> #DIV/0! | G12: =F12+Solicitud!B45 -> #DIV/0!
B13: Plazo (meses)
B14: Tasa anual
B15: Cuota (fórmula)
B16: Fecha 1er pago (opcional) | C16: =Solicitud!B40 -> 0
A18: # | B18: Fecha | C18: Saldo inicial | D18: Cuota | E18: Interés | F18: Capital | G18: Saldo final
A19: =IF(1<=$D$12,1,"") | B19: =IF(1<=$D$12,IF($C$16="","",EDATE($C$16,1-1)),"") | C19: =IF(1<=$D$12,$C$12,"") | D19: =IF(1<=$D$12,$F$12,"") | E19: =IF(1<=$D$12,C19*($E$12/12),"") | F19: =IF(1<=$D$12,D19-E19,"") | G19: =IF(1<=$D$12,MAX(0,C19-F19),"")
A20: =IF(2<=$D$12,2,"") | B20: =IF(2<=$D$12,IF($C$16="","",EDATE($C$16,2-1)),"") | C20: =IF(2<=$D$12,G19,"") | D20: =IF(1<=$D$12,$F$12,"") | E20: =IF(1<=$D$12,C20*($E$12/12),"") | F20: =IF(2<=$D$12,D20-E20,"") | G20: =IF(2<=$D$12,MAX(0,C20-F20),"")
A21: =IF(3<=$D$12,3,"") | B21: =IF(3<=$D$12,IF($C$16="","",EDATE($C$16,3-1)),"") | C21: =IF(3<=$D$12,G20,"") | D21: =IF(1<=$D$12,$F$12,"") | E21: =IF(1<=$D$12,C21*($E$12/12),"") | F21: =IF(3<=$D$12,D21-E21,"") | G21: =IF(3<=$D$12,MAX(0,C21-F21),"")
A22: =IF(4<=$D$12,4,"") | B22: =IF(4<=$D$12,IF($C$16="","",EDATE($C$16,4-1)),"") | C22: =IF(4<=$D$12,G21,"") | D22: =IF(1<=$D$12,$F$12,"") | E22: =IF(1<=$D$12,C22*($E$12/12),"") | F22: =IF(4<=$D$12,D22-E22,"") | G22: =IF(4<=$D$12,MAX(0,C22-F22),"")
A23: =IF(5<=$D$12,5,"") | B23: =IF(5<=$D$12,IF($C$16="","",EDATE($C$16,5-1)),"") | C23: =IF(5<=$D$12,G22,"") | D23: =IF(1<=$D$12,$F$12,"") | E23: =IF(1<=$D$12,C23*($E$12/12),"") | F23: =IF(5<=$D$12,D23-E23,"") | G23: =IF(5<=$D$12,MAX(0,C23-F23),"")
A24: =IF(6<=$D$12,6,"") | B24: =IF(6<=$D$12,IF($C$16="","",EDATE($C$16,6-1)),"") | C24: =IF(6<=$D$12,G23,"") | D24: =IF(1<=$D$12,$F$12,"") | E24: =IF(1<=$D$12,C24*($E$12/12),"") | F24: =IF(6<=$D$12,D24-E24,"") | G24: =IF(6<=$D$12,MAX(0,C24-F24),"")
A25: =IF(7<=$D$12,7,"") | B25: =IF(7<=$D$12,IF($C$16="","",EDATE($C$16,7-1)),"") | C25: =IF(7<=$D$12,G24,"") | D25: =IF(1<=$D$12,$F$12,"") | E25: =IF(1<=$D$12,C25*($E$12/12),"") | F25: =IF(7<=$D$12,D25-E25,"") | G25: =IF(7<=$D$12,MAX(0,C25-F25),"")
A26: =IF(8<=$D$12,8,"") | B26: =IF(8<=$D$12,IF($C$16="","",EDATE($C$16,8-1)),"") | C26: =IF(8<=$D$12,G25,"") | D26: =IF(1<=$D$12,$F$12,"") | E26: =IF(1<=$D$12,C26*($E$12/12),"") | F26: =IF(8<=$D$12,D26-E26,"") | G26: =IF(8<=$D$12,MAX(0,C26-F26),"")
A27: =IF(9<=$D$12,9,"") | B27: =IF(9<=$D$12,IF($C$16="","",EDATE($C$16,9-1)),"") | C27: =IF(9<=$D$12,G26,"") | D27: =IF(1<=$D$12,$F$12,"") | E27: =IF(1<=$D$12,C27*($E$12/12),"") | F27: =IF(9<=$D$12,D27-E27,"") | G27: =IF(9<=$D$12,MAX(0,C27-F27),"")
A28: =IF(10<=$D$12,10,"") | B28: =IF(10<=$D$12,IF($C$16="","",EDATE($C$16,10-1)),"") | C28: =IF(10<=$D$12,G27,"") | D28: =IF(1<=$D$12,$F$12,"") | E28: =IF(1<=$D$12,C28*($E$12/12),"") | F28: =IF(10<=$D$12,D28-E28,"") | G28: =IF(10<=$D$12,MAX(0,C28-F28),"")
A29: =IF(11<=$D$12,11,"") | B29: =IF(11<=$D$12,IF($C$16="","",EDATE($C$16,11-1)),"") | C29: =IF(11<=$D$12,G28,"") | D29: =IF(1<=$D$12,$F$12,"") | E29: =IF(1<=$D$12,C29*($E$12/12),"") | F29: =IF(11<=$D$12,D29-E29,"") | G29: =IF(11<=$D$12,MAX(0,C29-F29),"")
A30: =IF(12<=$D$12,12,"") | B30: =IF(12<=$D$12,IF($C$16="","",EDATE($C$16,12-1)),"") | C30: =IF(12<=$D$12,G29,"") | D30: =IF(1<=$D$12,$F$12,"") | E30: =IF(1<=$D$12,C30*($E$12/12),"") | F30: =IF(12<=$D$12,D30-E30,"") | G30: =IF(12<=$D$12,MAX(0,C30-F30),"")
A31: =IF(13<=$D$12,13,"") | B31: =IF(13<=$D$12,IF($C$16="","",EDATE($C$16,13-1)),"") | C31: =IF(13<=$D$12,G30,"") | D31: =IF(1<=$D$12,$F$12,"") | E31: =IF(1<=$D$12,C31*($E$12/12),"") | F31: =IF(13<=$D$12,D31-E31,"") | G31: =IF(13<=$D$12,MAX(0,C31-F31),"")
A32: =IF(14<=$D$12,14,"") | B32: =IF(14<=$D$12,IF($C$16="","",EDATE($C$16,14-1)),"") | C32: =IF(14<=$D$12,G31,"") | D32: =IF(1<=$D$12,$F$12,"") | E32: =IF(1<=$D$12,C32*($E$12/12),"") | F32: =IF(14<=$D$12,D32-E32,"") | G32: =IF(14<=$D$12,MAX(0,C32-F32),"")
A33: =IF(15<=$D$12,15,"") | B33: =IF(15<=$D$12,IF($C$16="","",EDATE($C$16,15-1)),"") | C33: =IF(15<=$D$12,G32,"") | D33: =IF(1<=$D$12,$F$12,"") | E33: =IF(1<=$D$12,C33*($E$12/12),"") | F33: =IF(15<=$D$12,D33-E33,"") | G33: =IF(15<=$D$12,MAX(0,C33-F33),"")
A34: =IF(16<=$D$12,16,"") | B34: =IF(16<=$D$12,IF($C$16="","",EDATE($C$16,16-1)),"") | C34: =IF(16<=$D$12,G33,"") | D34: =IF(1<=$D$12,$F$12,"") | E34: =IF(1<=$D$12,C34*($E$12/12),"") | F34: =IF(16<=$D$12,D34-E34,"") | G34: =IF(16<=$D$12,MAX(0,C34-F34),"")
A35: =IF(17<=$D$12,17,"") | B35: =IF(17<=$D$12,IF($C$16="","",EDATE($C$16,17-1)),"") | C35: =IF(17<=$D$12,G34,"") | D35: =IF(1<=$D$12,$F$12,"") | E35: =IF(1<=$D$12,C35*($E$12/12),"") | F35: =IF(17<=$D$12,D35-E35,"") | G35: =IF(17<=$D$12,MAX(0,C35-F35),"")
A36: =IF(18<=$D$12,18,"") | B36: =IF(18<=$D$12,IF($C$16="","",EDATE($C$16,18-1)),"") | C36: =IF(18<=$D$12,G35,"") | D36: =IF(1<=$D$12,$F$12,"") | E36: =IF(1<=$D$12,C36*($E$12/12),"") | F36: =IF(18<=$D$12,D36-E36,"") | G36: =IF(18<=$D$12,MAX(0,C36-F36),"")
A37: =IF(19<=$D$12,19,"") | B37: =IF(19<=$D$12,IF($C$16="","",EDATE($C$16,19-1)),"") | C37: =IF(19<=$D$12,G36,"") | D37: =IF(1<=$D$12,$F$12,"") | E37: =IF(1<=$D$12,C37*($E$12/12),"") | F37: =IF(19<=$D$12,D37-E37,"") | G37: =IF(19<=$D$12,MAX(0,C37-F37),"")
A38: =IF(20<=$D$12,20,"") | B38: =IF(20<=$D$12,IF($C$16="","",EDATE($C$16,20-1)),"") | C38: =IF(20<=$D$12,G37,"") | D38: =IF(1<=$D$12,$F$12,"") | E38: =IF(1<=$D$12,C38*($E$12/12),"") | F38: =IF(20<=$D$12,D38-E38,"") | G38: =IF(20<=$D$12,MAX(0,C38-F38),"")
A39: =IF(21<=$D$12,21,"") | B39: =IF(21<=$D$12,IF($C$16="","",EDATE($C$16,21-1)),"") | C39: =IF(21<=$D$12,G38,"") | D39: =IF(1<=$D$12,$F$12,"") | E39: =IF(1<=$D$12,C39*($E$12/12),"") | F39: =IF(21<=$D$12,D39-E39,"") | G39: =IF(21<=$D$12,MAX(0,C39-F39),"")
A40: =IF(22<=$D$12,22,"") | B40: =IF(22<=$D$12,IF($C$16="","",EDATE($C$16,22-1)),"") | C40: =IF(22<=$D$12,G39,"") | D40: =IF(1<=$D$12,$F$12,"") | E40: =IF(1<=$D$12,C40*($E$12/12),"") | F40: =IF(22<=$D$12,D40-E40,"") | G40: =IF(22<=$D$12,MAX(0,C40-F40),"")
A41: =IF(23<=$D$12,23,"") | B41: =IF(23<=$D$12,IF($C$16="","",EDATE($C$16,23-1)),"") | C41: =IF(23<=$D$12,G40,"") | D41: =IF(1<=$D$12,$F$12,"") | E41: =IF(1<=$D$12,C41*($E$12/12),"") | F41: =IF(23<=$D$12,D41-E41,"") | G41: =IF(23<=$D$12,MAX(0,C41-F41),"")
A42: =IF(24<=$D$12,24,"") | B42: =IF(24<=$D$12,IF($C$16="","",EDATE($C$16,24-1)),"") | C42: =IF(24<=$D$12,G41,"") | D42: =IF(1<=$D$12,$F$12,"") | E42: =IF(1<=$D$12,C42*($E$12/12),"") | F42: =IF(24<=$D$12,D42-E42,"") | G42: =IF(24<=$D$12,MAX(0,C42-F42),"")
A43: =IF(25<=$D$12,25,"") | B43: =IF(25<=$D$12,IF($C$16="","",EDATE($C$16,25-1)),"") | C43: =IF(25<=$D$12,G42,"") | D43: =IF(1<=$D$12,$F$12,"") | E43: =IF(1<=$D$12,C43*($E$12/12),"") | F43: =IF(25<=$D$12,D43-E43,"") | G43: =IF(25<=$D$12,MAX(0,C43-F43),"")
...
